Workbook

Sheet nithya
B1: Content player functionality
B2: MP4 Content
B3: Verify that a course can be created with a single MP4 content.
B4: Verify that the course with attached MP4 content can be enrolled by the learner
B5: Verify that the MP4 content can be launched from the catalog details page.
B6: Verify that the MP4 content can be launched from My Learning.
B7: Verify that the course moves to the Completed tab upon content completion.
B9: Verify that a course can be created with a single MP4 content and a pre-assessment.
B10: Verify that the course with attached MP4 content and pre-assessment can be enrolled.
B11: Verify that the MP4 content cannot be launched from the catalog details page without taking the pre-assessment.
B12: Verify that the MP4 content cannot be launched from My Learning without taking the pre-assessment.
B13: Verify that the pre-assessment can be taken and answered.
... B893: Verify that able to set mandatory access to user in Access setting
A894: Class Cancellation and Completion | B894: Verify course is created as Multi instance when the delivery type is choosed as Classroom/Virtual class
A895: Class Cancellation and Completion | B895: Verify course is not created as Multi instance when the delivery type is choosed as E-learning
A896: Class Cancellation and Completion | B896: Verify that the Cancellation option is available only for ILT/VC classes and not for E-learning classes.
A897: Class Cancellation and Completion | B897: Verify that the Cancellation option is available for ILT/VC classes at the instance level only.
A898: Class Cancellation and Completion | B898: Verify that class cancellation notification is triggered to the user when admin cancel the class
A899: Class Cancellation and Completion | B899: Verify that the 'Number of Instance' dropdown is disabled.
A900: Class Cancellation and Completion | B900: Verify that the admin does not have the privilege to perform any action on the 'Number of Instance' dropdown.
A901: Class Cancellation and Completion | B901: Verify that the admin can cancel an instance/class when there are no enrollments.
A902: Class Cancellation and Completion | B902: Verify that the admin can cancel an instance/class with enrollments in various states (Past, Future, Ongoing).
A903: Class Cancellation and Completion | B903: Verify that the 'Cancel' button is enabled only in the Edit - Class/Instance page.
A904: Class Cancellation and Completion | B904: Verify that the 'Cancel' button is enabled only when the Instance is either shown or hidden in the catalog.
A905: Class Cancellation and Completion | B905: Verify that the 'Cancel' button should not be available when the Instance is in the save draft state.
... A1142: Tenant creation | B1142: Verify that able to create a new tenant for Lite, Mid and Complex editions
B1143: Verify that able to login into the new tenant
B1144: Verify that data from existing tenant should not be visible in the new tenant
B1145: Verify all the modules are visible in the newly created tenants
B1146: Verify that the default learner portal is created for the newly created tenants
B1147: Table need to be added - subscribe

Sheet Praba
A1: Certification | B1: Verify the admin able to create a Certification with single instance and check created certification gets listed in the Certification list page Verify the created Certification will be displayed in Learner UI catalog in "Most Recent" section Verify the certification with single instance get auto enrolled via single click launch in catalog page Verify the enrolled certification course will be displayed in my learning To_complete tab Verify the learner able to launch and complete the course under certification via TP details page Verify the learner able to launch and complete the course under certification via My Leanrning page
A2: Certification | B2: Verify the admin able to create a Certification with multi instance and check created certification gets listed in the Certification list page Verify the created Certification will be displayed in Learner UI catalog in "Most Recent" section Verify the certification with single instance will not get auto enrolled via single click launch in catalog page ,only tp will get enrolled and learner need to select the class and enroll the course under certification Verify the enrolled certification course will be displayed in my learning To_complete tab Verify the learner able to launch and complete the course under certification via TP details page Verify the learner able to launch and complete the course under certification via My Leanrning page
A3: Certification | B3: Verify the admin able to create a Certification with 3 single instance and check created certification gets listed in the Certification list page Verify the Certification with 3 single instance get auto enrolled when admin enroll the certification in manage enrollment Verify the certification with all 3 single instance get auto enrolled via single click launch in catalog page Verify the enrolled certification courses are displayed in my learning To_complete tab(3 enrolled courses) Verify the learner able to launch and complete the all classes under certification via TP details page
A4: Certification | B4: Verify the admin able to create a Certification with 3 multi instance and check created certification gets listed in the Certification list page Verify the certification with all 3 multi instance will not get auto enrolled when admin enroll the certification in manage enrollment Verify the all instance will enroll through "View status/enroll learner to TP courses" screen for the certification with multi instance Verify the certification with all 3 multi instance will not auto enrolled via single click launch in catalog page only tp will get enrolled and learner need to select the class and enroll the course under certification Verify the enrolled certification courses are displayed in my learning To_complete tab(3 enrolled courses)
A5: Certification | B5: Verify admin able to create certification then add 3 modules with 2 single instance for each module Verify the certification single instance get auto enrolled via single click launch in catalog page for the certification with multiple modules Verify admin able to create certification then add 3 modules with 2 multi instance for each module Verify the certification multi instance will not get auto enrolled via single click launch in catalog page for the certification with multiple modules,learner needs to select and enroll it Verify the learner able to enroll and completed the certification in Tree view with module and without module Verify the learner able to enroll and completed the certification in Module view with module and without module
A6: Certification | B6: Verfiy the admin able to create Compliance Certification
A7: Certification | B7: Verify the Mandatory,Optional and Recommended access is not getting displayed in the Access setting when it is a Compliance TP
A8: Certification | B8: Verify the learner are automatically enrolled in the Compliance Certification via auto_register cron when their access is set.
A9: Certification | B9: Verify the Compliance Label is displayed after enrolling a Compliance Certification in TP details page and my dashboard certification/learning path section
A10: Certification | B10: Verify the Compliance Certification cannot be canceled as a learner
A11: Certification | B11: Verify the the Compliance certification gets expired after the expiry days
A12: Certification | B12: Verify the duplicate enrollments will not occur when same user attached to multiple learner group attached to the Certification
... A493: Transfer Enrollment - TP | B493: To verify that the Training plan will not be displayed when admin search in the not versioned cert or lp in transfer enrollment page

Sheet master_pivot

Sheet ALL1
A1: =MasterSheet_final!A1 -> S No | B1: =MasterSheet_final!B1 -> Module | C1: =MasterSheet_final!C1 -> Scenario | D1: =MasterSheet_final!D1 -> Status | E1: =MasterSheet_final!E1 -> Executed on | F1: =#REF! -> #REF! | G1: =MasterSheet_final!F1 -> Resource | H1: Week No | I1: Week | J1: Week Count
A2: =MasterSheet_final!A2 -> 1 | B2: =MasterSheet_final!B2 -> Tenant creation | C2: =MasterSheet_final!C2 -> Verify that able to create a new tenant for Lite, Mid and Complex editions | D2: =MasterSheet_final!D2 -> Pass | E2: =MasterSheet_final!E2 -> 45801 | F2: =#REF! -> #REF! | G2: =MasterSheet_final!F2 -> Nithya | H2: =IF(ISBLANK(E2)," ",WEEKNUM(E2,2)) -> 21 | I2: =if(H2=5,"27th Jan-2nd Feb", if(H2=6,"3rd Feb-9th Feb", if(H2=7,"10th Feb-16th Feb",if(H2=8,"17th Feb-23rd Feb", if(H2=9,"24th Feb-2nd March",if(H2=10,"3rd March - 9th March"," ")))))) | J2: =if(H2=5,"W1", if(H2=6,"W2", if(H2=7,"W3",if(H2=8,"W4", if(H2=9,"W5",if(H2=10,"W6"," "))))))
A3: =MasterSheet_final!A3 -> 2 | B3: =MasterSheet_final!B3 -> Tenant creation | C3: =MasterSheet_final!C3 -> Verify that able to login into the new tenant | D3: =MasterSheet_final!D3 -> Pass | E3: =MasterSheet_final!E3 -> 45801 | F3: =#REF! -> #REF! | G3: =MasterSheet_final!F3 -> Nithya | H3: =IF(ISBLANK(E3)," ",WEEKNUM(E3,2)) -> 21 | I3: =if(H3=5,"27th Jan-2nd Feb", if(H3=6,"3rd Feb-9th Feb", if(H3=7,"10th Feb-16th Feb",if(H3=8,"17th Feb-23rd Feb", if(H3=9,"24th Feb-2nd March",if(H3=10,"3rd March - 9th March"," ")))))) | J3: =if(H3=5,"W1", if(H3=6,"W2", if(H3=7,"W3",if(H3=8,"W4", if(H3=9,"W5",if(H3=10,"W6"," "))))))
A4: =MasterSheet_final!A4 -> 3 | B4: =MasterSheet_final!B4 -> Tenant creation | C4: =MasterSheet_final!C4 -> Verify that data from existing tenant should not be visible in the new tenant | D4: =MasterSheet_final!D4 -> Pass | E4: =MasterSheet_final!E4 -> 45801 | F4: =#REF! -> #REF! | G4: =MasterSheet_final!F4 -> Nithya | H4: =IF(ISBLANK(E4)," ",WEEKNUM(E4,2)) -> 21 | I4: =if(H4=5,"27th Jan-2nd Feb", if(H4=6,"3rd Feb-9th Feb", if(H4=7,"10th Feb-16th Feb",if(H4=8,"17th Feb-23rd Feb", if(H4=9,"24th Feb-2nd March",if(H4=10,"3rd March - 9th March"," ")))))) | J4: =if(H4=5,"W1", if(H4=6,"W2", if(H4=7,"W3",if(H4=8,"W4", if(H4=9,"W5",if(H4=10,"W6"," "))))))
A5: =MasterSheet_final!A5 -> 4 | B5: =MasterSheet_final!B5 -> Tenant creation | C5: =MasterSheet_final!C5 -> Verify all the modules are visible in the newly created tenants | D5: =MasterSheet_final!D5 -> Pass | E5: =MasterSheet_final!E5 -> 45801 | F5: =#REF! -> #REF! | G5: =MasterSheet_final!F5 -> Nithya | H5: =IF(ISBLANK(E5)," ",WEEKNUM(E5,2)) -> 21 | I5: =if(H5=5,"27th Jan-2nd Feb", if(H5=6,"3rd Feb-9th Feb", if(H5=7,"10th Feb-16th Feb",if(H5=8,"17th Feb-23rd Feb", if(H5=9,"24th Feb-2nd March",if(H5=10,"3rd March - 9th March"," ")))))) | J5: =if(H5=5,"W1", if(H5=6,"W2", if(H5=7,"W3",if(H5=8,"W4", if(H5=9,"W5",if(H5=10,"W6"," "))))))
A6: =MasterSheet_final!A6 -> 5 | B6: =MasterSheet_final!B6 -> Tenant creation | C6: =MasterSheet_final!C6 -> Verify that the default learner portal is created for the newly created tenants | D6: =MasterSheet_final!D6 -> Pass | E6: =MasterSheet_final!E6 -> 45801 | F6: =#REF! -> #REF! | G6: =MasterSheet_final!F6 -> Nithya | H6: =IF(ISBLANK(E6)," ",WEEKNUM(E6,2)) -> 21 | I6: =if(H6=5,"27th Jan-2nd Feb", if(H6=6,"3rd Feb-9th Feb", if(H6=7,"10th Feb-16th Feb",if(H6=8,"17th Feb-23rd Feb", if(H6=9,"24th Feb-2nd March",if(H6=10,"3rd March - 9th March"," ")))))) | J6: =if(H6=5,"W1", if(H6=6,"W2", if(H6=7,"W3",if(H6=8,"W4", if(H6=9,"W5",if(H6=10,"W6"," "))))))
A7: =#REF! -> #REF! | B7: =#REF! -> #REF! | C7: =#REF! -> #REF! | D7: =#REF! -> #REF! | E7: =#REF! -> #REF! | F7: =#REF! -> #REF! | G7: =#REF! -> #REF! | H7: =IF(ISBLANK(E7)," ",WEEKNUM(E7,2)) -> #REF! | I7: =if(H7=5,"27th Jan-2nd Feb", if(H7=6,"3rd Feb-9th Feb", if(H7=7,"10th Feb-16th Feb",if(H7=8,"17th Feb-23rd Feb", if(H7=9,"24th Feb-2nd March",if(H7=10,"3rd March - 9th March"," ")))))) -> #REF! | J7: =if(H7=5,"W1", if(H7=6,"W2", if(H7=7,"W3",if(H7=8,"W4", if(H7=9,"W5",if(H7=10,"W6"," ")))))) -> #REF!
A8: =MasterSheet_final!A7 -> 6 | B8: =MasterSheet_final!B7 -> Portal creation | C8: =MasterSheet_final!C7 -> Verify that able to create a new portal to the tenant | D8: =MasterSheet_final!D7 -> Pass | E8: =MasterSheet_final!E7 -> 45801 | F8: =#REF! -> #REF! | G8: =MasterSheet_final!F7 -> Nithya | H8: =IF(ISBLANK(E8)," ",WEEKNUM(E8,2)) -> 21 | I8: =if(H8=5,"27th Jan-2nd Feb", if(H8=6,"3rd Feb-9th Feb", if(H8=7,"10th Feb-16th Feb",if(H8=8,"17th Feb-23rd Feb", if(H8=9,"24th Feb-2nd March",if(H8=10,"3rd March - 9th March"," ")))))) | J8: =if(H8=5,"W1", if(H8=6,"W2", if(H8=7,"W3",if(H8=8,"W4", if(H8=9,"W5",if(H8=10,"W6"," "))))))
A9: =MasterSheet_final!A8 -> 7 | B9: =MasterSheet_final!B8 -> Portal creation | C9: =MasterSheet_final!C8 -> Verifty that able to login into the newly created portal | D9: =MasterSheet_final!D8 -> Pass | E9: =MasterSheet_final!E8 -> 45801 | F9: =#REF! -> #REF! | G9: =MasterSheet_final!F8 -> Nithya | H9: =IF(ISBLANK(E9)," ",WEEKNUM(E9,2)) -> 21 | I9: =if(H9=5,"27th Jan-2nd Feb", if(H9=6,"3rd Feb-9th Feb", if(H9=7,"10th Feb-16th Feb",if(H9=8,"17th Feb-23rd Feb", if(H9=9,"24th Feb-2nd March",if(H9=10,"3rd March - 9th March"," ")))))) | J9: =if(H9=5,"W1", if(H9=6,"W2", if(H9=7,"W3",if(H9=8,"W4", if(H9=9,"W5",if(H9=10,"W6"," "))))))
A10: =MasterSheet_final!A9 -> 8 | B10: =MasterSheet_final!B9 -> Portal creation | C10: =MasterSheet_final!C9 -> Verify that able to create template to the newly created portal | D10: =MasterSheet_final!D9 -> Pass | E10: =MasterSheet_final!E9 -> 45801 | F10: =#REF! -> #REF! | G10: =MasterSheet_final!F9 -> Nithya | H10: =IF(ISBLANK(E10)," ",WEEKNUM(E10,2)) -> 21 | I10: =if(H10=5,"27th Jan-2nd Feb", if(H10=6,"3rd Feb-9th Feb", if(H10=7,"10th Feb-16th Feb",if(H10=8,"17th Feb-23rd Feb", if(H10=9,"24th Feb-2nd March",if(H10=10,"3rd March - 9th March"," ")))))) | J10: =if(H10=5,"W1", if(H10=6,"W2", if(H10=7,"W3",if(H10=8,"W4", if(H10=9,"W5",if(H10=10,"W6"," "))))))
A11: =MasterSheet_final!A10 -> 9 | B11: =MasterSheet_final!B10 -> Portal creation | C11: =MasterSheet_final!C10 -> Verify that a default portal is created automatically while creating a new portal | D11: =MasterSheet_final!D10 -> Pass | E11: =MasterSheet_final!E10 -> 45801 | F11: =#REF! -> #REF! | G11: =MasterSheet_final!F10 -> Nithya | H11: =IF(ISBLANK(E11)," ",WEEKNUM(E11,2)) -> 21 | I11: =if(H11=5,"27th Jan-2nd Feb", if(H11=6,"3rd Feb-9th Feb", if(H11=7,"10th Feb-16th Feb",if(H11=8,"17th Feb-23rd Feb", if(H11=9,"24th Feb-2nd March",if(H11=10,"3rd March - 9th March"," ")))))) | J11: =if(H11=5,"W1", if(H11=6,"W2", if(H11=7,"W3",if(H11=8,"W4", if(H11=9,"W5",if(H11=10,"W6"," "))))))
A12: =MasterSheet_final!A11 -> 10 | B12: =MasterSheet_final!B11 -> Portal creation | C12: =MasterSheet_final!C11 -> Verify that able to create multiple template to the single portal | D12: =MasterSheet_final!D11 -> Pass | E12: =MasterSheet_final!E11 -> 45801 | F12: =#REF! -> #REF! | G12: =MasterSheet_final!F11 -> Nithya | H12: =IF(ISBLANK(E12)," ",WEEKNUM(E12,2)) -> 21 | I12: =if(H12=5,"27th Jan-2nd Feb", if(H12=6,"3rd Feb-9th Feb", if(H12=7,"10th Feb-16th Feb",if(H12=8,"17th Feb-23rd Feb", if(H12=9,"24th Feb-2nd March",if(H12=10,"3rd March - 9th March"," ")))))) | J12: =if(H12=5,"W1", if(H12=6,"W2", if(H12=7,"W3",if(H12=8,"W4", if(H12=9,"W5",if(H12=10,"W6"," "))))))
A13: =MasterSheet_final!A12 -> 11 | B13: =MasterSheet_final!B12 -> Portal creation | C13: =MasterSheet_final!C12 -> Verify that able to set only one default template to the the portal | D13: =MasterSheet_final!D12 -> Pass | E13: =MasterSheet_final!E12 -> 45801 | F13: =#REF! -> #REF! | G13: =MasterSheet_final!F12 -> Nithya | H13: =IF(ISBLANK(E13)," ",WEEKNUM(E13,2)) -> 21 | I13: =if(H13=5,"27th Jan-2nd Feb", if(H13=6,"3rd Feb-9th Feb", if(H13=7,"10th Feb-16th Feb",if(H13=8,"17th Feb-23rd Feb", if(H13=9,"24th Feb-2nd March",if(H13=10,"3rd March - 9th March"," ")))))) | J13: =if(H13=5,"W1", if(H13=6,"W2", if(H13=7,"W3",if(H13=8,"W4", if(H13=9,"W5",if(H13=10,"W6"," "))))))
A14: =MasterSheet_final!A13 -> 12 | B14: =MasterSheet_final!B13 -> Portal creation | C14: =MasterSheet_final!C13 -> Verify that multiple portals can be created in the tenant with same portal url but domain name should be different | D14: =MasterSheet_final!D13 -> Pass | E14: =MasterSheet_final!E13 -> 45801 | F14: =#REF! -> #REF! | G14: =MasterSheet_final!F13 -> Nithya | H14: =IF(ISBLANK(E14)," ",WEEKNUM(E14,2)) -> 21 | I14: =if(H14=5,"27th Jan-2nd Feb", if(H14=6,"3rd Feb-9th Feb", if(H14=7,"10th Feb-16th Feb",if(H14=8,"17th Feb-23rd Feb", if(H14=9,"24th Feb-2nd March",if(H14=10,"3rd March - 9th March"," ")))))) | J14: =if(H14=5,"W1", if(H14=6,"W2", if(H14=7,"W3",if(H14=8,"W4", if(H14=9,"W5",if(H14=10,"W6"," "))))))
A15: =MasterSheet_final!A14 -> 13 | B15: =MasterSheet_final!B14 -> Portal creation | C15: =MasterSheet_final!C14 -> Verify that should not able to create portal with same domain name | D15: =MasterSheet_final!D14 -> Pass | E15: =MasterSheet_final!E14 -> 45801 | F15: =#REF! -> #REF! | G15: =MasterSheet_final!F14 -> Nithya | H15: =IF(ISBLANK(E15)," ",WEEKNUM(E15,2)) -> 21 | I15: =if(H15=5,"27th Jan-2nd Feb", if(H15=6,"3rd Feb-9th Feb", if(H15=7,"10th Feb-16th Feb",if(H15=8,"17th Feb-23rd Feb", if(H15=9,"24th Feb-2nd March",if(H15=10,"3rd March - 9th March"," ")))))) | J15: =if(H15=5,"W1", if(H15=6,"W2", if(H15=7,"W3",if(H15=8,"W4", if(H15=9,"W5",if(H15=10,"W6"," "))))))
A16: =MasterSheet_final!A15 -> 14 | B16: =MasterSheet_final!B15 -> Portal creation | C16: =MasterSheet_final!C15 -> Verify that able to clone the portal | D16: =MasterSheet_final!D15 -> Pass | E16: =MasterSheet_final!E15 -> 45801 | F16: =#REF! -> #REF! | G16: =MasterSheet_final!F15 -> Nithya | H16: =IF(ISBLANK(E16)," ",WEEKNUM(E16,2)) -> 21 | I16: =if(H16=5,"27th Jan-2nd Feb", if(H16=6,"3rd Feb-9th Feb", if(H16=7,"10th Feb-16th Feb",if(H16=8,"17th Feb-23rd Feb", if(H16=9,"24th Feb-2nd March",if(H16=10,"3rd March - 9th March"," ")))))) | J16: =if(H16=5,"W1", if(H16=6,"W2", if(H16=7,"W3",if(H16=8,"W4", if(H16=9,"W5",if(H16=10,"W6"," "))))))
A17: =MasterSheet_final!A16 -> 15 | B17: =MasterSheet_final!B16 -> Portal creation | C17: =MasterSheet_final!C16 -> Verify that able to copy the portal url using the copy link icon | D17: =MasterSheet_final!D16 -> Pass | E17: =MasterSheet_final!E16 -> 45801 | F17: =#REF! -> #REF! | G17: =MasterSheet_final!F16 -> Nithya | H17: =IF(ISBLANK(E17)," ",WEEKNUM(E17,2)) -> 21 | I17: =if(H17=5,"27th Jan-2nd Feb", if(H17=6,"3rd Feb-9th Feb", if(H17=7,"10th Feb-16th Feb",if(H17=8,"17th Feb-23rd Feb", if(H17=9,"24th Feb-2nd March",if(H17=10,"3rd March - 9th March"," ")))))) | J17: =if(H17=5,"W1", if(H17=6,"W2", if(H17=7,"W3",if(H17=8,"W4", if(H17=9,"W5",if(H17=10,"W6"," "))))))
A18: =MasterSheet_final!A17 -> 16 | B18: =MasterSheet_final!B17 -> Portal creation | C18: =MasterSheet_final!C17 -> Verify that able to edit the portal and change the domain name and portal url | D18: =MasterSheet_final!D17 -> Pass | E18: =MasterSheet_final!E17 -> 45801 | F18: =#REF! -> #REF! | G18: =MasterSheet_final!F17 -> Nithya | H18: =IF(ISBLANK(E18)," ",WEEKNUM(E18,2)) -> 21 | I18: =if(H18=5,"27th Jan-2nd Feb", if(H18=6,"3rd Feb-9th Feb", if(H18=7,"10th Feb-16th Feb",if(H18=8,"17th Feb-23rd Feb", if(H18=9,"24th Feb-2nd March",if(H18=10,"3rd March - 9th March"," ")))))) | J18: =if(H18=5,"W1", if(H18=6,"W2", if(H18=7,"W3",if(H18=8,"W4", if(H18=9,"W5",if(H18=10,"W6"," "))))))
A19: =MasterSheet_final!A18 -> 17 | B19: =MasterSheet_final!B18 -> Portal creation | C19: =MasterSheet_final!C18 -> Verify that able to login into the portal which is edited (could not able to login as the old one) | D19: =MasterSheet_final!D18 -> Pass | E19: =MasterSheet_final!E18 -> 45801 | F19: =#REF! -> #REF! | G19: =MasterSheet_final!F18 -> Nithya | H19: =IF(ISBLANK(E19)," ",WEEKNUM(E19,2)) -> 21 | I19: =if(H19=5,"27th Jan-2nd Feb", if(H19=6,"3rd Feb-9th Feb", if(H19=7,"10th Feb-16th Feb",if(H19=8,"17th Feb-23rd Feb", if(H19=9,"24th Feb-2nd March",if(H19=10,"3rd March - 9th March"," ")))))) | J19: =if(H19=5,"W1", if(H19=6,"W2", if(H19=7,"W3",if(H19=8,"W4", if(H19=9,"W5",if(H19=10,"W6"," "))))))
... A143: =MasterSheet_final!A142 -> 141 | B143: =MasterSheet_final!B142 -> Admin Group | C143: =MasterSheet_final!C142 -> Verify whether the Code is autogenerated correctly when we enable the Code Convention | D143: =MasterSheet_final!D142 -> Pass | E143: =MasterSheet_final!E142 -> 45804 | F143: =#REF! -> #REF! | G143: =MasterSheet_final!F142 -> Selva | H143: =IF(ISBLANK(E143)," ",WEEKNUM(E143,2)) -> 22 | I143: =if(H143=5,"27th Jan-2nd Feb", if(H143=6,"3rd Feb-9th Feb", if(H143=7,"10th Feb-16th Feb",if(H143=8,"17th Feb-23rd Feb", if(H143=9,"24th Feb-2nd March",if(H143=10,"3rd March - 9th March"," ")))))) | J143: =if(H143=5,"W1", if(H143=6,"W2", if(H143=7,"W3",if(H143=8,"W4", if(H143=9,"W5",if(H143=10,"W6"," "))))))
A144: =#REF! -> #REF! | B144: =#REF! -> #REF! | C144: =#REF! -> #REF! | D144: =#REF! -> #REF! | E144: =#REF! -> #REF! | F144: =#REF! -> #REF! | G144: =#REF! -> #REF! | H144: =IF(ISBLANK(E144)," ",WEEKNUM(E144,2)) -> #REF! | I144: =if(H144=5,"27th Jan-2nd Feb", if(H144=6,"3rd Feb-9th Feb", if(H144=7,"10th Feb-16th Feb",if(H144=8,"17th Feb-23rd Feb", if(H144=9,"24th Feb-2nd March",if(H144=10,"3rd March - 9th March"," ")))))) -> #REF! | J144: =if(H144=5,"W1", if(H144=6,"W2", if(H144=7,"W3",if(H144=8,"W4", if(H144=9,"W5",if(H144=10,"W6"," ")))))) -> #REF!
A145: =#REF! -> #REF! | B145: =#REF! -> #REF! | C145: =#REF! -> #REF! | D145: =#REF! -> #REF! | E145: =#REF! -> #REF! | F145: =#REF! -> #REF! | G145: =#REF! -> #REF! | H145: =IF(ISBLANK(E145)," ",WEEKNUM(E145,2)) -> #REF! | I145: =if(H145=5,"27th Jan-2nd Feb", if(H145=6,"3rd Feb-9th Feb", if(H145=7,"10th Feb-16th Feb",if(H145=8,"17th Feb-23rd Feb", if(H145=9,"24th Feb-2nd March",if(H145=10,"3rd March - 9th March"," ")))))) -> #REF! | J145: =if(H145=5,"W1", if(H145=6,"W2", if(H145=7,"W3",if(H145=8,"W4", if(H145=9,"W5",if(H145=10,"W6"," ")))))) -> #REF!
A146: =#REF! -> #REF! | B146: =#REF! -> #REF! | C146: =#REF! -> #REF! | D146: =#REF! -> #REF! | E146: =#REF! -> #REF! | F146: =#REF! -> #REF! | G146: =#REF! -> #REF! | H146: =IF(ISBLANK(E146)," ",WEEKNUM(E146,2)) -> #REF! | I146: =if(H146=5,"27th Jan-2nd Feb", if(H146=6,"3rd Feb-9th Feb", if(H146=7,"10th Feb-16th Feb",if(H146=8,"17th Feb-23rd Feb", if(H146=9,"24th Feb-2nd March",if(H146=10,"3rd March - 9th March"," ")))))) -> #REF! | J146: =if(H146=5,"W1", if(H146=6,"W2", if(H146=7,"W3",if(H146=8,"W4", if(H146=9,"W5",if(H146=10,"W6"," ")))))) -> #REF!
A147: =#REF! -> #REF! | B147: =#REF! -> #REF! | C147: =#REF! -> #REF! | D147: =#REF! -> #REF! | E147: =#REF! -> #REF! | F147: =#REF! -> #REF! | G147: =#REF! -> #REF! | H147: =IF(ISBLANK(E147)," ",WEEKNUM(E147,2)) -> #REF! | I147: =if(H147=5,"27th Jan-2nd Feb", if(H147=6,"3rd Feb-9th Feb", if(H147=7,"10th Feb-16th Feb",if(H147=8,"17th Feb-23rd Feb", if(H147=9,"24th Feb-2nd March",if(H147=10,"3rd March - 9th March"," ")))))) -> #REF! | J147: =if(H147=5,"W1", if(H147=6,"W2", if(H147=7,"W3",if(H147=8,"W4", if(H147=9,"W5",if(H147=10,"W6"," ")))))) -> #REF!
A148: =MasterSheet_final!A143 -> 142 | B148: =MasterSheet_final!B143 -> Admin Group | C148: =MasterSheet_final!C143 -> Verify whether we cannot delete the Default Admin Groups | D148: =MasterSheet_final!D143 -> Pass | E148: =MasterSheet_final!E143 -> 45800 | F148: =#REF! -> #REF! | G148: =MasterSheet_final!F143 -> Selva | H148: =IF(ISBLANK(E148)," ",WEEKNUM(E148,2)) -> 21 | I148: =if(H148=5,"27th Jan-2nd Feb", if(H148=6,"3rd Feb-9th Feb", if(H148=7,"10th Feb-16th Feb",if(H148=8,"17th Feb-23rd Feb", if(H148=9,"24th Feb-2nd March",if(H148=10,"3rd March - 9th March"," ")))))) | J148: =if(H148=5,"W1", if(H148=6,"W2", if(H148=7,"W3",if(H148=8,"W4", if(H148=9,"W5",if(H148=10,"W6"," "))))))
A149: =MasterSheet_final!A144 -> 143 | B149: =MasterSheet_final!B144 -> Admin Group | C149: =MasterSheet_final!C144 -> Verify whether we can Create,Edit,Activate and Suspend a Admin Group as a Custom Admin user | D149: =MasterSheet_final!D144 -> Pass | E149: =MasterSheet_final!E144 -> 45800 | F149: =#REF! -> #REF! | G149: =MasterSheet_final!F144 -> Selva | H149: =IF(ISBLANK(E149)," ",WEEKNUM(E149,2)) -> 21 | I149: =if(H149=5,"27th Jan-2nd Feb", if(H149=6,"3rd Feb-9th Feb", if(H149=7,"10th Feb-16th Feb",if(H149=8,"17th Feb-23rd Feb", if(H149=9,"24th Feb-2nd March",if(H149=10,"3rd March - 9th March"," ")))))) | J149: =if(H149=5,"W1", if(H149=6,"W2", if(H149=7,"W3",if(H149=8,"W4", if(H149=9,"W5",if(H149=10,"W6"," "))))))
A150: =MasterSheet_final!A145 -> 144 | B150: =MasterSheet_final!B145 -> Admin Group | C150: =MasterSheet_final!C145 -> Verify whether the Admin group Access is set to the created Group based on the Logged in user | D150: =MasterSheet_final!D145 -> Pass | E150: =MasterSheet_final!E145 -> 45808 | F150: =#REF! -> #REF! | G150: =MasterSheet_final!F145 -> Selva | H150: =IF(ISBLANK(E150)," ",WEEKNUM(E150,2)) -> 22 | I150: =if(H150=5,"27th Jan-2nd Feb", if(H150=6,"3rd Feb-9th Feb", if(H150=7,"10th Feb-16th Feb",if(H150=8,"17th Feb-23rd Feb", if(H150=9,"24th Feb-2nd March",if(H150=10,"3rd March - 9th March"," ")))))) | J150: =if(H150=5,"W1", if(H150=6,"W2", if(H150=7,"W3",if(H150=8,"W4", if(H150=9,"W5",if(H150=10,"W6"," "))))))
A151: =MasterSheet_final!A146 -> 145 | B151: =MasterSheet_final!B146 -> Admin Group | C151: =MasterSheet_final!C146 -> Verify whether the Admin Group goes to unpublished state after the Valid till Date | D151: =MasterSheet_final!D146 -> Pass | E151: =MasterSheet_final!E146 -> 45800 | F151: =#REF! -> #REF! | G151: =MasterSheet_final!F146 -> Selva | H151: =IF(ISBLANK(E151)," ",WEEKNUM(E151,2)) -> 21 | I151: =if(H151=5,"27th Jan-2nd Feb", if(H151=6,"3rd Feb-9th Feb", if(H151=7,"10th Feb-16th Feb",if(H151=8,"17th Feb-23rd Feb", if(H151=9,"24th Feb-2nd March",if(H151=10,"3rd March - 9th March"," ")))))) | J151: =if(H151=5,"W1", if(H151=6,"W2", if(H151=7,"W3",if(H151=8,"W4", if(H151=9,"W5",if(H151=10,"W6"," "))))))
A152: =MasterSheet_final!A147 -> 146 | B152: =MasterSheet_final!B147 -> Learner Group | C152: =MasterSheet_final!C147 -> Verify that the admin able to access the Learner Group Create/Edit option from Quick Access | D152: =MasterSheet_final!D147 -> Pass | E152: =MasterSheet_final!E147 -> 45807 | F152: =#REF! -> #REF! | G152: =MasterSheet_final!F147 -> Selva | H152: =IF(ISBLANK(E152)," ",WEEKNUM(E152,2)) -> 22 | I152: =if(H152=5,"27th Jan-2nd Feb", if(H152=6,"3rd Feb-9th Feb", if(H152=7,"10th Feb-16th Feb",if(H152=8,"17th Feb-23rd Feb", if(H152=9,"24th Feb-2nd March",if(H152=10,"3rd March - 9th March"," ")))))) | J152: =if(H152=5,"W1", if(H152=6,"W2", if(H152=7,"W3",if(H152=8,"W4", if(H152=9,"W5",if(H152=10,"W6"," "))))))
A153: =MasterSheet_final!A148 -> 147 | B153: =MasterSheet_final!B148 -> Learner Group | C153: =MasterSheet_final!C148 -> Verify that the admin able to access the Learner Group under People module from toggle menu | D153: =MasterSheet_final!D148 -> Pass | E153: =MasterSheet_final!E148 -> 45807 | F153: =#REF! -> #REF! | G153: =MasterSheet_final!F148 -> Selva | H153: =IF(ISBLANK(E153)," ",WEEKNUM(E153,2)) -> 22 | I153: =if(H153=5,"27th Jan-2nd Feb", if(H153=6,"3rd Feb-9th Feb", if(H153=7,"10th Feb-16th Feb",if(H153=8,"17th Feb-23rd Feb", if(H153=9,"24th Feb-2nd March",if(H153=10,"3rd March - 9th March"," ")))))) | J153: =if(H153=5,"W1", if(H153=6,"W2", if(H153=7,"W3",if(H153=8,"W4", if(H153=9,"W5",if(H153=10,"W6"," "))))))
A154: =MasterSheet_final!A149 -> 148 | B154: =MasterSheet_final!B149 -> Learner Group | C154: =MasterSheet_final!C149 -> Verify that the below listed details will be displayed when admin click create learner group -Title -Code -Valid till -Attributes -Include learners and exclude learners | D154: =MasterSheet_final!D149 -> Pass | E154: =MasterSheet_final!E149 -> 45807 | F154: =#REF! -> #REF! | G154: =MasterSheet_final!F149 -> Selva | H154: =IF(ISBLANK(E154)," ",WEEKNUM(E154,2)) -> 22 | I154: =if(H154=5,"27th Jan-2nd Feb", if(H154=6,"3rd Feb-9th Feb", if(H154=7,"10th Feb-16th Feb",if(H154=8,"17th Feb-23rd Feb", if(H154=9,"24th Feb-2nd March",if(H154=10,"3rd March - 9th March"," ")))))) | J154: =if(H154=5,"W1", if(H154=6,"W2", if(H154=7,"W3",if(H154=8,"W4", if(H154=9,"W5",if(H154=10,"W6"," "))))))
A155: =MasterSheet_final!A150 -> 149 | B155: =MasterSheet_final!B150 -> Learner Group | C155: =MasterSheet_final!C150 -> Verify that admin able to create Learner Group -Create a New Role "Common Role" and Create a new admin group "Common Admin group" with role as "Common Role" -Manually add "Prabaadmin" user then login into admin site -Create a learner group | D155: =MasterSheet_final!D150 -> Pass | E155: =MasterSheet_final!E150 -> 45807 | F155: =#REF! -> #REF! | G155: =MasterSheet_final!F150 -> Selva | H155: =IF(ISBLANK(E155)," ",WEEKNUM(E155,2)) -> 22 | I155: =if(H155=5,"27th Jan-2nd Feb", if(H155=6,"3rd Feb-9th Feb", if(H155=7,"10th Feb-16th Feb",if(H155=8,"17th Feb-23rd Feb", if(H155=9,"24th Feb-2nd March",if(H155=10,"3rd March - 9th March"," ")))))) | J155: =if(H155=5,"W1", if(H155=6,"W2", if(H155=7,"W3",if(H155=8,"W4", if(H155=9,"W5",if(H155=10,"W6"," "))))))
A156: =MasterSheet_final!A151 -> 150 | B156: =MasterSheet_final!B151 -> Learner Group | C156: =MasterSheet_final!C151 -> Verify whether we can able to Create/Update/Activate/Suspend a Learner Group as a Custom Admin user | D156: =MasterSheet_final!D151 -> Pass | E156: =MasterSheet_final!E151 -> 45807 | F156: =#REF! -> #REF! | G156: =MasterSheet_final!F151 -> Selva | H156: =IF(ISBLANK(E156)," ",WEEKNUM(E156,2)) -> 22 | I156: =if(H156=5,"27th Jan-2nd Feb", if(H156=6,"3rd Feb-9th Feb", if(H156=7,"10th Feb-16th Feb",if(H156=8,"17th Feb-23rd Feb", if(H156=9,"24th Feb-2nd March",if(H156=10,"3rd March - 9th March"," ")))))) | J156: =if(H156=5,"W1", if(H156=6,"W2", if(H156=7,"W3",if(H156=8,"W4", if(H156=9,"W5",if(H156=10,"W6"," "))))))
A157: =MasterSheet_final!A152 -> 151 | B157: =MasterSheet_final!B152 -> Learner Group | C157: =MasterSheet_final!C152 -> Verify that the admin able to remove the added learner and check it displayed in exlude learners section | D157: =MasterSheet_final!D152 -> Pass | E157: =MasterSheet_final!E152 -> 45808 | F157: =#REF! -> #REF! | G157: =MasterSheet_final!F152 -> Selva | H157: =IF(ISBLANK(E157)," ",WEEKNUM(E157,2)) -> 22 | I157: =if(H157=5,"27th Jan-2nd Feb", if(H157=6,"3rd Feb-9th Feb", if(H157=7,"10th Feb-16th Feb",if(H157=8,"17th Feb-23rd Feb", if(H157=9,"24th Feb-2nd March",if(H157=10,"3rd March - 9th March"," ")))))) | J157: =if(H157=5,"W1", if(H157=6,"W2", if(H157=7,"W3",if(H157=8,"W4", if(H157=9,"W5",if(H157=10,"W6"," "))))))
A158: =MasterSheet_final!A153 -> 152 | B158: =MasterSheet_final!B153 -> Learner Group | C158: =MasterSheet_final!C153 -> Verify that the Select Domain will be selected all domains when create Learner group | D158: =MasterSheet_final!D153 -> Pass | E158: =MasterSheet_final!E153 -> 45807 | F158: =#REF! -> #REF! | G158: =MasterSheet_final!F153 -> Selva | H158: =IF(ISBLANK(E158)," ",WEEKNUM(E158,2)) -> 22 | I158: =if(H158=5,"27th Jan-2nd Feb", if(H158=6,"3rd Feb-9th Feb", if(H158=7,"10th Feb-16th Feb",if(H158=8,"17th Feb-23rd Feb", if(H158=9,"24th Feb-2nd March",if(H158=10,"3rd March - 9th March"," ")))))) | J158: =if(H158=5,"W1", if(H158=6,"W2", if(H158=7,"W3",if(H158=8,"W4", if(H158=9,"W5",if(H158=10,"W6"," "))))))
A159: =MasterSheet_final!A154 -> 153 | B159: =MasterSheet_final!B154 -> Learner Group | C159: =MasterSheet_final!C154 -> Verify that the learner will be added in backend when admin select Department attribute | D159: =MasterSheet_final!D154 -> Pass | E159: =MasterSheet_final!E154 -> 45808 | F159: =#REF! -> #REF! | G159: =MasterSheet_final!F154 -> Selva | H159: =IF(ISBLANK(E159)," ",WEEKNUM(E159,2)) -> 22 | I159: =if(H159=5,"27th Jan-2nd Feb", if(H159=6,"3rd Feb-9th Feb", if(H159=7,"10th Feb-16th Feb",if(H159=8,"17th Feb-23rd Feb", if(H159=9,"24th Feb-2nd March",if(H159=10,"3rd March - 9th March"," ")))))) | J159: =if(H159=5,"W1", if(H159=6,"W2", if(H159=7,"W3",if(H159=8,"W4", if(H159=9,"W5",if(H159=10,"W6"," "))))))
... A173: =MasterSheet_final!A168 -> 167 | B173: =MasterSheet_final!B168 -> Learner Group | C173: =MasterSheet_final!C168 -> Verify that the learner will get add in the learner group if two departments are added in the same attribute(Ex:Depart1,depart2) | D173: =MasterSheet_final!D168 -> Pass | E173: =MasterSheet_final!E168 -> 45810 | F173: =#REF! -> #REF! | G173: =MasterSheet_final!F168 -> Selva | H173: =IF(ISBLANK(E173)," ",WEEKNUM(E173,2)) -> 23 | I173: =if(H173=5,"27th Jan-2nd Feb", if(H173=6,"3rd Feb-9th Feb", if(H173=7,"10th Feb-16th Feb",if(H173=8,"17th Feb-23rd Feb", if(H173=9,"24th Feb-2nd March",if(H173=10,"3rd March - 9th March"," ")))))) | J173: =if(H173=5,"W1", if(H173=6,"W2", if(H173=7,"W3",if(H173=8,"W4", if(H173=9,"W5",if(H173=10,"W6"," "))))))
A174: =#REF! -> #REF! | B174: =#REF! -> #REF! | C174: =#REF! -> #REF! | D174: =#REF! -> #REF! | E174: =#REF! -> #REF! | F174: =#REF! -> #REF! | G174: =#REF! -> #REF! | H174: =IF(ISBLANK(E174)," ",WEEKNUM(E174,2)) -> #REF! | I174: =if(H174=5,"27th Jan-2nd Feb", if(H174=6,"3rd Feb-9th Feb", if(H174=7,"10th Feb-16th Feb",if(H174=8,"17th Feb-23rd Feb", if(H174=9,"24th Feb-2nd March",if(H174=10,"3rd March - 9th March"," ")))))) -> #REF! | J174: =if(H174=5,"W1", if(H174=6,"W2", if(H174=7,"W3",if(H174=8,"W4", if(H174=9,"W5",if(H174=10,"W6"," ")))))) -> #REF!
A175: =MasterSheet_final!A169 -> 168 | B175: =MasterSheet_final!B169 -> Learner Group | C175: =MasterSheet_final!C169 -> Verify that the Selected Domain and selected attribute,the learner will get added to the learner group Ex:User-depart1 and domain1 | D175: =MasterSheet_final!D169 -> Pass | E175: =MasterSheet_final!E169 -> 45810 | F175: =#REF! -> #REF! | G175: =MasterSheet_final!F169 -> Selva | H175: =IF(ISBLANK(E175)," ",WEEKNUM(E175,2)) -> 23 | I175: =if(H175=5,"27th Jan-2nd Feb", if(H175=6,"3rd Feb-9th Feb", if(H175=7,"10th Feb-16th Feb",if(H175=8,"17th Feb-23rd Feb", if(H175=9,"24th Feb-2nd March",if(H175=10,"3rd March - 9th March"," ")))))) | J175: =if(H175=5,"W1", if(H175=6,"W2", if(H175=7,"W3",if(H175=8,"W4", if(H175=9,"W5",if(H175=10,"W6"," "))))))
A176: =MasterSheet_final!A170 -> 169 | B176: =MasterSheet_final!B170 -> Learner Group | C176: =MasterSheet_final!C170 -> Verify that the all the learners belonging to the selected Domain will get added to the group if admin selected domain without attribute Ex: If only Domain1 is selected, the user belonging to Domain1 and users part of Domain1 will be added to the group i.e If User A belongs to Domain 1 and User B is part of Domain1 & Domain2. When a learner group is created with Domain1, both User A & B will get added to the group. | D176: =MasterSheet_final!D170 -> Pass | E176: =MasterSheet_final!E170 -> 45811 | F176: =#REF! -> #REF! | G176: =MasterSheet_final!F170 -> Selva | H176: =IF(ISBLANK(E176)," ",WEEKNUM(E176,2)) -> 23 | I176: =if(H176=5,"27th Jan-2nd Feb", if(H176=6,"3rd Feb-9th Feb", if(H176=7,"10th Feb-16th Feb",if(H176=8,"17th Feb-23rd Feb", if(H176=9,"24th Feb-2nd March",if(H176=10,"3rd March - 9th March"," ")))))) | J176: =if(H176=5,"W1", if(H176=6,"W2", if(H176=7,"W3",if(H176=8,"W4", if(H176=9,"W5",if(H176=10,"W6"," "))))))
...

Sheet Pivot Table 6

Sheet Dashboard
Z2: =Y2/$AG$2 -> 0 | AH2: =AG2-R7 -> 4698
Y3: =if(isblank(X3), $AF$1,X3+Y2) | Z3: =if(isblank(Y3),"",Y3/$AG$2)
Y4: =if(isblank(X4), $AF$1,X4+Y3) | Z4: =if(isblank(Y4),"",Y4/$AG$2)
Y5: =if(isblank(X5), $AF$1,X5+Y4) | Z5: =if(isblank(Y5),"",Y5/$AG$2)
Y6: =if(isblank(X6), $AF$1,X6+Y5) | Z6: =if(isblank(Y6),"",Y6/$AG$2)
Y7: =if(isblank(X7), $AF$1,X7+Y6) | Z7: =if(isblank(Y7),"",Y7/$AG$2)
Y8: =if(isblank(X8), $AF$1,X8+Y7) | Z8: =if(isblank(Y8),"",Y8/$AG$2)
Y9: =if(isblank(X9), $AF$1,X9+Y8) | Z9: =if(isblank(Y9),"",Y9/$AG$2)
Y10: =if(isblank(X10), $AF$1,X10+Y9) | Z10: =if(isblank(Y10),"",Y10/$AG$2)
Y11: =if(isblank(X11), $AF$1,X11+Y10) | Z11: =if(isblank(Y11),"",Y11/$AG$2)
Y12: =if(isblank(X12), $AF$1,X12+Y11) | Z12: =if(isblank(Y12),"",Y12/$AG$2)
Y13: =if(isblank(X13), $AF$1,X13+Y12) | Z13: =if(isblank(Y13),"",Y13/$AG$2)
Y14: =if(isblank(X14), $AF$1,X14+Y13) | Z14: =if(isblank(Y14),"",Y14/$AG$2)
... Y17: =if(isblank(X17), $AF$1,X17+Y16) | Z17: =if(isblank(Y17),"",Y17/$AG$2)
Y18: =if(isblank(W18), $AF$1,Y18+Y17)

Sheet MasterSheet_final
A1: S No | B1: Module | C1: Scenario | D1: Status | E1: Executed on | F1: Resource | G1: Jira Ticket#
A2: 1 | B2: Tenant creation | C2: Verify that able to create a new tenant for Lite, Mid and Complex editions | D2: Pass | E2: 45801 | F2: Nithya
A3: 2 | B3: Tenant creation | C3: Verify that able to login into the new tenant | D3: Pass | E3: 45801 | F3: Nithya
A4: 3 | B4: Tenant creation | C4: Verify that data from existing tenant should not be visible in the new tenant | D4: Pass | E4: 45801 | F4: Nithya
A5: 4 | B5: Tenant creation | C5: Verify all the modules are visible in the newly created tenants | D5: Pass | E5: 45801 | F5: Nithya
A6: 5 | B6: Tenant creation | C6: Verify that the default learner portal is created for the newly created tenants | D6: Pass | E6: 45801 | F6: Nithya
A7: 6 | B7: Portal creation | C7: Verify that able to create a new portal to the tenant | D7: Pass | E7: 45801 | F7: Nithya
A8: 7 | B8: Portal creation | C8: Verifty that able to login into the newly created portal | D8: Pass | E8: 45801 | F8: Nithya
A9: 8 | B9: Portal creation | C9: Verify that able to create template to the newly created portal | D9: Pass | E9: 45801 | F9: Nithya
A10: 9 | B10: Portal creation | C10: Verify that a default portal is created automatically while creating a new portal | D10: Pass | E10: 45801 | F10: Nithya
A11: 10 | B11: Portal creation | C11: Verify that able to create multiple template to the single portal | D11: Pass | E11: 45801 | F11: Nithya
A12: 11 | B12: Portal creation | C12: Verify that able to set only one default template to the the portal | D12: Pass | E12: 45801 | F12: Nithya
A13: 12 | B13: Portal creation | C13: Verify that multiple portals can be created in the tenant with same portal url but domain name should be different | D13: Pass | E13: 45801 | F13: Nithya
... A264: 263 | B264: Organization | C264: To Verify that admin can able to export the child organizations | D264: Pass | E264: 45798 | F264: Manikandan
A265: 264 | B265: Organization | C265: To Verify the export sheet contains Name, User Name, Email ID, Job Title, User Type, Manager Name, Association Type, added on | D265: Pass | E265: 45798
A266: 265 | B266: Organization | C266: To Verify that the child organization action is disabled when the count is zero | D266: Pass | E266: 45798 | F266: Manikandan
A267: 266 | B267: Organization | C267: To Verify the association type shows whether it is mapped with primary or other organization | D267: Pass | E267: 45800 | F267: Manikandan
A268: 267 | B268: Organization | C268: To Verify the suspend icon is available for the who has edit permission | D268: Pass | E268: 45797 | F268: Manikandan
A269: 268 | B269: Organization | C269: -To Verify suspend an organization which has active users -Will display message Suspending the organization will remove all users associated with it, would you like to proceed? | D269: Pass | E269: 45798 | F269: Manikandan
A270: 269 | B270: Organization | C270: -To Verify click yes on suspend alert popup box - The users should get unmapped | D270: Pass | E270: 45797 | F270: Manikandan
A271: 270 | B271: Organization | C271: -To Verify suspend an organization which has child organizations -Will display message Suspending the parent organization will make its associated child organization to will move one level higher, would you like to proceed? | D271: Pass | E271: 45797 | F271: Manikandan
A272: 271 | B272: Organization | C272: -To Verify suspend an organization which has child organizations -The child organization will be moved on one level up | D272: Pass | E272: 45797 | F272: Manikandan
A273: 272 | B273: Organization | C273: To Verify the created organizations are not listing in other Tenant which is not having access | D273: Pass | E273: 45811 | F273: Manikandan
A274: 273 | B274: Organization | C274: To Verify that update button should not be enabled in edit page untill the admin edits it | D274: Pass | E274: 45804 | F274: Manikandan
A275: 274 | B275: Organization | C275: To Verify that discard button should not be enabled in edit page untill the admin edits it | D275: Pass | E275: 45797 | F275: Manikandan
A276: 275 | B276: Organization | C276: To Verify that save button will be enabled only if all the mandatory fields are filled. | D276: Pass | E276: 45797 | F276: Manikandan
A277: 276 | B277: Organization | C277: "-To Verify after clicking save the access pop up box should get opened with the message -This organization will be assigned to 'All Learners' group and the admin groups that you're part of. Please validate your decision. - And Yes, proceed and No, modify the access buttons should be listed in the pop up box" | D277: Pass | E277: 45797 | F277: Manikandan
... A417: 416 | B417: User | C417: Verify that user should be landed in Collaboration hub page when having both instructor and Manager role | D417: Pass | E417: 45800 | F417: Manikandan
A418: 417 | C418: Verify that user should be landed in Admin page when having admin access alone and also with instructor and Manager role | D418: Pass | E418: 45800 | F418: Manikandan
A419: 418 | B419: User | C419: Verify that uploaded profile image is showing in Learner and Admin side after user logged in | D419: Pass | E419: 45800 | F419: Manikandan
A420: 419 | B420: User | C420: Verify that Associated Learner and Admin groups are showing correctly for which the user is part of domain | D420: Pass | E420: 45812 | F420: Manikandan
A421: 420 | B421: User | C421: Verify that One profile link is generated successfully after the user is created | D421: Pass | E421: 45800 | F421: Manikandan
A422: 421 | B422: User | C422: Verify that able to view the One profile summary page with the generated link | D422: Pass | E422: 45800 | F422: Manikandan
A423: 422 | B423: User | C423: Verify that the Custom fields can be added in to the user page as Mandatory and Non-mandatory | D423: Pass | E423: 45801 | F423: Manikandan
A424: 423 | B424: User | C424: Verify that could not able to save or update the user unless the Mandatory custom field is filled | D424: Pass | E424: 45801 | F424: Manikandan
A425: 424 | B425: User | C425: Verify that if only the admin who has access to the user is able to view or edit that user. | D425: Pass | E425: 45800 | F425: Manikandan
A426: 425 | B426: User | C426: Verify that suspended users cannot able to login | D426: Pass | E426: 45800 | F426: Manikandan
A427: 426 | B427: User | C427: Verify that could not able to remove the instructor role when the user is having upcoming ILT / VC classess | D427: Pass | E427: 45800 | F427: Manikandan
A428: 427 | B428: User | C428: Verify that able to add direct and other Manager to the user | D428: Pass | E428: 45800 | F428: Manikandan
A429: 428 | B429: User | C429: Verify that should not able to add the direct Manager as other Manager | D429: Pass | E429: 45800 | F429: Manikandan
...

Sheet TO_do
A1: S No | B1: Module | C1: Scenario | D1: Status | E1: Executed on | F1: Resource | G1: Jira Ticket#
A2: 1 | B2: Tenant creation | C2: Verify that able to create a new tenant for Lite, Mid and Complex editions
A3: 2 | B3: Tenant creation | C3: Verify that able to login into the new tenant
A4: 3 | B4: Tenant creation | C4: Verify that data from existing tenant should not be visible in the new tenant
A5: 4 | B5: Tenant creation | C5: Verify all the modules are visible in the newly created tenants
A6: 5 | B6: Tenant creation | C6: Verify that the default learner portal is created for the newly created tenants
A7: 6 | B7: Portal creation | C7: Verify that able to create a new portal to the tenant
A8: 7 | B8: Portal creation | C8: Verifty that able to login into the newly created portal
A9: 8 | B9: Portal creation | C9: Verify that able to create template to the newly created portal
A10: 9 | B10: Portal creation | C10: Verify that a default portal is created automatically while creating a new portal
A11: 10 | B11: Portal creation | C11: Verify that able to create multiple template to the single portal
A12: 11 | B12: Portal creation | C12: Verify that able to set only one default template to the the portal
A13: 12 | B13: Portal creation | C13: Verify that multiple portals can be created in the tenant with same portal url but domain name should be different
... A26: 25 | B26: Portal creation | C26: Verify that the created portals are showing in the switch portal section of Admin home page and learner home page
A27: 26 | B27: Admin Role | C27: Verify able to create a admin role with all the privilages | D27: Pass | E27: 45941
A28: 27 | B28: Admin Role | C28: Verify the search functionality is working correctly | D28: Pass | E28: 45941
A29: 28 | B29: Admin Role | C29: Verify whether we can edit a admin Role | D29: Pass | E29: 45941
A30: 29 | B30: Admin Role | C30: Verify whether we can delete admin Role it is not mapped to any entity | D30: Pass | E30: 45941
A31: 30 | B31: Admin Role | C31: Verify whether the deleted roles are not listing in the List page | D31: Pass | E31: 45941
A32: 31 | B32: Admin Role | C32: Verify whether we cannot delete admin Role it is mapped to any entity | D32: Pass | E32: 45941
A33: 32 | B33: Admin Role | C33: Verify whether all the modules are displayed when we click on Privilage icon | D33: Pass | E33: 45941
A34: 33 | B34: Admin Role | C34: Verify whether name of the admin role acts as a mandatory field | D34: Pass | E34: 45941
A35: 34 | B35: Admin Role | C35: Verify while clicking on Delete privilage for any module will enable View, Create and Edit | D35: Pass | E35: 45941
A36: 35 | B36: Admin Role | C36: Verify whether the Admin Role created in one tenant is not visible in another tenant | D36: Pass | E36: 45941
A37: 36 | B37: Admin Role | C37: Verify whether the Sort function is working correctly | D37: Pass | E37: 45941
A38: 37 | B38: Admin Role | C38: Verify whether the Export function is working correctly (Export as CSV, PDF and Excel) | D38: Pass | E38: 45941
... A44: 43 | B44: Admin Role | C44: Verify whether the Edit and delete icon is in disabled state for Custom Admin Role | D44: Pass | E44: 45941
A45: 44 | B45: Admin Role | C45: Verify whether the Save and Close button works correctly | D45: Pass
A46: 45 | B46: Admin Role | C46: Verify whether we can edit the privilages for the Admin role created by Customer | D46: Pass
A47: 46 | B47: Admin Role | C47: Verify whether it does not allow to edit a default admin role (E1 Super Admin) | D47: Pass
A48: 47 | B48: Admin Role | C48: Verify whether we can able to view a module when the view permission is only given | D48: Pass
A49: 48 | B49: Admin Role | C49: Verify whether we can able to Create and View a module when the Create and view permission is only given | D49: Pass
A50: 49 | B50: Admin Role | C50: Verify whether we can able to Create, view, edit a module when the Create, view, edit permission is only given | D50: Pass
A51: 50 | B51: Admin Role | C51: Verify whether we can able to Create, edit , view,delete a module when the delete permission is given | D51: Pass
A52: 51 | B52: Admin Role | C52: Verify for the following scenerio for all the module privileges - User 1 is attached to a admin group1 and the role privilage is Course Create - User 1 is also a part of admin group2 which has Course Create and Edit privilages - When we login as user 1 we can able to Create and Edit couse | D52: Pass
A53: 52 | B53: Admin Role | C53: Verify whether the Survey module is displayed in all the Creation page when Learing Module - Enable Survey module - Disable | D53: Pass
A54: 53 | B54: Admin Role | C54: Verify whether the Assessment module is displayed in all the Creation page when Learing Module - Enable Assessment module - Disable | D54: Pass
A55: 54 | B55: Admin Role | C55: Verify whether the Skills module is displayed in all the Creation page when Learing Module - Enable Skills module - Disable | D55: Pass
A56: 55 | B56: Admin Role | C56: Verify whether the Observation Checklist module is displayed in all the Creation page when Learing Module - Enable OJT module - Disable | D56: Pass
... A58: 57 | B58: Admin Role | C58: Verify whether the Discussion module is displayed in all the Creation page when Learing Module - Enable Discussion module - Disable | D58: Pass
...

Sheet Sheet43
A1: 4982
D2: High | E2: Medium | F2: Low
A3: 38 | B3: Failed | C3: =A3/A1 -> 0.0076274589 | D3: 0 | E3: 0.0025 | F3: 0.005
D4: 0 | E4: =E3*A1 -> 12.455 | F4: =F3*A1 -> 24.91
A5: 4944 | B5: Passed

Sheet Reports
A1: Survey Report | B1: Verify that the course displays in the Training Title section after completing the survey.
B2: Verify that when dates are selected but start and end times are not entered, the "Generate Report" button remains disabled.
B3: Verify that users are displayed based on the selected date and Time.
B4: Verify the export functionality of the report(e.g., CSV, Excel, PDF)
B5: Verify that the "Generate Report" button is enabled without entering the start date and end date.
B6: When a date is selected, the "Generate Report" button should remain disabled unless both the start and end times are filled.
B7: Verify that past and future ILT, VC, and E-learning sessions,after adding a survey and completion criteria, are able to generate reports.
A8: Assessment Report | B8: Verify that the course displays in the Training Title section after completing the Assessment.
B9: Verify that when dates are selected but start and end times are not entered, the "Generate Report" button remains disabled.
B10: Verify that users are displayed based on the selected date and Time.
B11: Verify the export functionality of the report(e.g., CSV, Excel, PDF).
B12: Verify that the "Generate Report" button is enabled without entering the start date and end date.
B13: When a date is selected, the "Generate Report" button should remain disabled unless both the start and end times are filled.
B14: Verify that past and future ILT, VC, and E-learning sessions,after adding a Assessment and completion criteria, are able to generate reports.

Sheet Agile_pivot
A1: #REF! | Y1: #REF! | AM1: #REF!
T2: Status
S3: Executed on | T3: Fail | U3: Hold | V3: Pass
S4: 45684 | T4: 23 | U4: 1 | V4: 49
S5: 45685 | T5: 15 | U5: 1 | V5: 61

Sheet Merge_Tickets_17.9
A1: Ticket No | B1: Summary | C1: Assignee | D1: Reporter | E1: Validated by | F1: Status | G1: Comments | H1: QA Resource | I1: Trunk Status | K1: Trunk Comments
A2: IRIS-3826 | B2: Dashboard>>Issues in Learner Playlist section | C2: Santhosh Phadmanabhan | D2: Selvakumar | E2: Selvakumar | F2: Pass | H2: Selva
A3: IRIS-4071 | B3: When cloning ILT classes in bulk, after checking for conflicts and clicking the 'Save' button, no success message is displayed, even though the classes are successfully cloned | C3: Divyasree TK | D3: Vijayaraja S | F3: Pass | H3: Nithya
A4: IRIS-4121 | B4: Learner >> Interaction studio >> Click here cannot redirect to Next Tab | C4: Subin Rajan | D4: Pragatheeshwaran V | H4: NA
A5: IRIS-4118 | B5: Interaction Studio->The H5P content created is not appearing on the Iris content page. | C5: Subin Rajan | D5: Arivazhagan Pachamuthu | E5: Arivazhagan Pachamuthu | F5: Pass | H5: NA
A6: IRIS-4220 | B6: Organisation Export result issue | C6: Manideep kumar | D6: Rajeshwari M | H6: Nithya
A7: IRIS-4168 | B7: Build 22.17 Issues - Learning path creation success message is incorrect. | C7: Archana G | D7: Archana G | E7: Sudha | F7: Partial | G7: Publishing the priced LP still displays the same message "Changing the price will impact the order and cancellation. Details update successfully" | H7: Duplicate
A8: IRIS-4161 | B8: Build 22.17 Issues - When you add a content while creating a course and then delete it , the page redirects to content listing page. | C8: Tamilvanan S | D8: Archana G | E8: Sudha | F8: Pass | H8: Tamil
A9: IRIS-4182 | B9: Prod issue- When admin updates the course title, database still shows the old title in the master_title field. | C9: sundarapandianp | D9: Dhivya Dharshini C | E9: Sudha | F9: Pass | H9: Duplicate
A10: IRIS-4163 | B10: Build 22.17 Issues - While creating a Learning path, when we modify the access, the default admin group and learner groups a not shown. | C10: Tamilvanan S | D10: Archana G | E10: Sudha | F10: Fail | G10: Still access is blank when doing "Modify Access" in the Learning Path | H10: Tamil
A11: IRIS-4166 | B11: Build 22.17 Issues - Content Description is missing and unpublish button is not enabled for previously published contents. | C11: anuradhab | D11: Archana G | E11: Sudha | F11: Fail | G11: Randomly checked the last content in the QA enviornment and the Description was blank. | H11: anuradhab
A12: IRIS-4172 | B12: Prod issue- Some random SCORM contents are encountering a 'Not Found code 404' error when previewed in the admin site and while launching in the learner site. | C12: anuradhab | D12: Dhivya Dharshini C | E12: Sudha | F12: Pass | H12: anuradhab
A13: IRIS-4193 | B13: Prod Issue - Issue with Optional Enrollments Being Marked as Mandatory in Course/Training Plan | C13: Ramesh K | D13: Sudha Balaji | E13: Sudha | F13: Partial | G13: Issue addressed for enrollments from admin. As a learner the enrollment is still marked as mandatory | H13: Duplicate
A14: IRIS-4173 | B14: Prod issue- While toggling from the learner site to the admin site encountering 'Internal server error 500'. This issue is inconsistent. | C14: Selva | D14: Dhivya Dharshini C | E14: Sudha | F14: Pass | G14: During the course of validation we did not encounter this issue even once, so this can be treated resolved. | H14: Selva
A15: IRIS-4176 | B15: Prod issue- Prerequisite issues | C15: Selvakumar | D15: Dhivya Dharshini C | E15: Sudha | F15: Pass | H15: Selva
A16: IRIS-3621 | B16: Metadata Library - All the languages other than English displayed in the base tenant are not showing in the newly created tenants | C16: Bharath | D16: nithyas | E16: nithyas | F16: Hold | G16: Tenant creation is not working - Ayyappan fixing | H16: nithyas
A17: IRIS-3888 | B17: In announcement screen it shows in JSON format in Change log | C17: Sunil Kumar Girdhar | D17: Vijayaraja S | F17: Pass | H17: Bala | I17: Hold | K17: Old values are updated as expected with text format and new values are getting updated according to the field update
A18: IRIS-4174 | B18: The ILT class is not getting canceled when the min seats are not occupied | C18: sundarapandianp | D18: Selvakumar | E18: Selvakumar | F18: Hold | G18: Cron is not working in QA - Unable to test this ticket | H18: Selva
A19: IRIS-4157 | B19: Enrolled count is shown as zero in the enrollment section though the TP has active enrollments. | C19: Sudha Balaji | D19: Dhivya Dharshini C | E19: Sudha | F19: Pass | H19: Bala | I19: Closed | K19: Enrolled count of Tp courses are displayed as expected either enroll from learner and admin side
A20: IRIS-4181 | B20: Learner->The Terms and Conditions popup is not appearing for admin users when they land on the learner site for the first time. | C20: Mathivanan S | D20: Arivazhagan Pachamuthu | E20: Arivazhagan Pachamuthu | F20: Pass | H20: Arivu
A21: IRIS-3901 | B21: course listing page as the course has multiple instances, clicking on the respective icon, a message gets displayed as 'No matching result found.' | C21: sharmiladevir | D21: Vijayaraja S | F21: Pass | H21: Bala | I21: Closed | K21: It displays the mult instance classes when I click the respective icon in the Multi instance class by loading
A22: IRIS-4167 | B22: Future date announcements are not visible on the Learner side | C22: Edwin Andrews | D22: Tamilvanan S | E22: Tamilvanan | F22: Pass | H22: Tamilvanan S | I22: Closed
A23: IRIS-4160 | B23: Prod issue- When a course is set to hide in catalog status, users who are already enrolled, completed and in progress status unable to see the class and its content | C23: Vadivel M | D23: Dhivya Dharshini C | E23: Sudha | F23: Pass | H23: Divya
A24: IRIS-3934 | B24: Learner>>Create Survey>>The save as draft is not enabled when entering the survey title. | C24: Tamilvanan S | D24: Tamilvanan S | E24: Tamilvanan | F24: Pass | H24: Tamilvanan S | I24: Closed | K24: New ticket has been created EAT1-938
A25: IRIS-4133 | B25: Admin->Training Plan->In the Training Plan, the filter disappears from the UI when navigating to either the Edit Certification page or the Edit Learning Path page. | C25: Santhosh Phadmanabhan | D25: Arivazhagan Pachamuthu | E25: Arivazhagan Pachamuthu | F25: Pass | H25: Arivu
A26: IRIS-4103 | B26: Preference >> Learner UI >> Giving CEU targets In Learner Site is Not fetching. | C26: Indhumathy Prathaban | D26: Pragatheeshwaran V | H26: Divya
A27: IRIS-4183 | B27: Learner->TP->Content Player->Multiple times, the spinner and 'No Results Found' message are displayed along with empty space, before the actual content loads | C27: sharmiladevir | D27: Arivazhagan Pachamuthu | E27: Arivazhagan Pachamuthu | F27: Reopened | H27: Arivu
A28: IRIS-4053 | B28: UI Overlap in Manage Enrollments: Search & Sort Options Overlap Filters | C28: Vadivel Chinnasamy | D28: Vijayaraja S | F28: Pass | H28: Divya
A29: IRIS-4085 | B29: Learner UI - Login Issue (400 Bad Request) | C29: Ayyappan Sekar | D29: Ramesh Subramanian | H29: Mani
A30: EAT1-559 | B30: Issues with cron migration | C30: Manideep kumar | D30: Syed Thanveer J | E30: Sudha | F30: NA | G30: Need to validate during the next migration. | H30: Selva
A31: EAT1-500 | B31: Admin>Content>Incorrect preview of content is displayed in preview when the content is versioned | C31: anuradhab | D31: anuradha | E31: anuradhab | F31: Re-opened | G31: Reported issue is fixed for url type content only. The same need to be fixed for other content types | H31: anuradha
A32: EAT1-553 | B32: Learner>Course Enrollment>There is an enrollment section displayed in the course details page when the course is already enrolled by the learner | C32: anuradhab | D32: Mohan | E32: anuradhab | F32: Pass | H32: anuradha
A33: EAT1-497 | B33: Expiry>>Class details is not displaying in details page for the following scenario | C33: Prabavathi | D33: Vadivel M | E33: Selvakumar | H33: Selva
A34: IRIS-4102 | B34: In the One-Profile Page, the Expiration Date of the completed course is not displaying. | C34: Sharmila | D34: Vijayaraja | F34: Pass | H34: Tamil | K34: Validated this issue, still expiration date of the completed course is not displaying on PTP summary
A35: IRIS-3891 | B35: Instructor checklist is also showing to the learner. | C35: Arunkumar | D35: Vijayaraja | F35: Pass | H35: Selva
A36: IRIS-4196 | B36: The completion certificate is not working properly in AAAE Production Environment. | C36: Ashutosh | D36: Dhineshkumar | E36: Sudha | F36: Pass | H36: Mani
A37: EAT1-388 | B37: Learner - Content player - Duration tracker for Brightcove content is incorrect in size | C37: Vadivelc | D37: Nithya | E37: nithyas | H37: Nithya
A38: EAT1-542 | B38: Issues in Dynamic Sharable Link | C38: Vadivel M | D38: Selvakumar | E38: Selvakumar | F38: Pass | H38: Selva
A39: IRIS-3283 | B39: Order>> Is allowing to create and approve the order without entering Country and state | C39: Bharath | D39: Nithya | E39: nithyas | F39: Re-opened | H39: Nithya
A40: IRIS-3820 | B40: Learner - Content player - Post assessment resume functionality need to to be developed | C40: Ramesh K | D40: Nithya | E40: nithyas | H40: Nithya
...

Sheet Merge_Tickets_17.14
A1: Ticket No | B1: Summary | C1: Assignee | D1: Reporter | E1: Validated by | F1: Status | G1: Comments | H1: QA Resource | I1: Trunk Status | J1: Trunk Comments
B2: https://expertusone.atlassian.net/browse/IRIS-4282 | H2: Team
B3: https://expertusone.atlassian.net/browse/EAT1-747-SSO | H3: Arivu
B4: https://expertusone.atlassian.net/browse/IRIS-4286-Overdue | H4: Anuradha

Sheet Sheet37
